<?xml version="1.0"?>
<sdf version="1.7">
  <model name="simple_car">
    <pose>0 0 0.35 0 0 0</pose>
    <link name="chassis">
      <inertial>
        <mass>1200</mass>
        <inertia>
          <ixx>400</ixx>
          <iyy>1200</iyy>
          <izz>1300</izz>
          <ixy>0</ixy>
          <ixz>0</ixz>
          <iyz>0</iyz>
        </inertia>
      </inertial>
      <collision name="chassis_collision">
        <geometry>
          <box>
            <size>2.4 1.2 0.6</size>
          </box>
        </geometry>
      </collision>
      <visual name="chassis_visual">
        <geometry>
          <box>
            <size>2.4 1.2 0.6</size>
          </box>
        </geometry>
        <material>
          <ambient>0.1 0.1 0.1 1</ambient>
          <diffuse>0.2 0.2 0.2 1</diffuse>
        </material>
      </visual>
    </link>

    <link name="wheel_fl">
      <pose>0.8 0.65 0.2 1.5708 0 0</pose>
      <inertial>
        <mass>20</mass>
        <inertia>
          <ixx>0.6</ixx>
          <iyy>0.6</iyy>
          <izz>0.6</izz>
          <ixy>0</ixy>
          <ixz>0</ixz>
          <iyz>0</iyz>
        </inertia>
      </inertial>
      <collision name="wheel_fl_collision">
        <geometry>
          <cylinder>
            <radius>0.3</radius>
            <length>0.2</length>
          </cylinder>
        </geometry>
      </collision>
      <visual name="wheel_fl_visual">
        <geometry>
          <cylinder>
            <radius>0.3</radius>
            <length>0.2</length>
          </cylinder>
        </geometry>
      </visual>
    </link>

    <link name="wheel_fr">
      <pose>0.8 -0.65 0.2 1.5708 0 0</pose>
      <inertial>
        <mass>20</mass>
        <inertia>
          <ixx>0.6</ixx>
          <iyy>0.6</iyy>
          <izz>0.6</izz>
          <ixy>0</ixy>
          <ixz>0</ixz>
          <iyz>0</iyz>
        </inertia>
      </inertial>
      <collision name="wheel_fr_collision">
        <geometry>
          <cylinder>
            <radius>0.3</radius>
            <length>0.2</length>
          </cylinder>
        </geometry>
      </collision>
      <visual name="wheel_fr_visual">
        <geometry>
          <cylinder>
            <radius>0.3</radius>
            <length>0.2</length>
          </cylinder>
        </geometry>
      </visual>
    </link>

    <link name="wheel_rl">
      <pose>-0.8 0.65 0.2 1.5708 0 0</pose>
      <inertial>
        <mass>20</mass>
        <inertia>
          <ixx>0.6</ixx>
          <iyy>0.6</iyy>
          <izz>0.6</izz>
          <ixy>0</ixy>
          <ixz>0</ixz>
          <iyz>0</iyz>
        </inertia>
      </inertial>
      <collision name="wheel_rl_collision">
        <geometry>
          <cylinder>
            <radius>0.3</radius>
            <length>0.2</length>
          </cylinder>
        </geometry>
      </collision>
      <visual name="wheel_rl_visual">
        <geometry>
          <cylinder>
            <radius>0.3</radius>
            <length>0.2</length>
          </cylinder>
        </geometry>
      </visual>
    </link>

    <link name="wheel_rr">
      <pose>-0.8 -0.65 0.2 1.5708 0 0</pose>
      <inertial>
        <mass>20</mass>
        <inertia>
          <ixx>0.6</ixx>
          <iyy>0.6</iyy>
          <izz>0.6</izz>
          <ixy>0</ixy>
          <ixz>0</ixz>
          <iyz>0</iyz>
        </inertia>
      </inertial>
      <collision name="wheel_rr_collision">
        <geometry>
          <cylinder>
            <radius>0.3</radius>
            <length>0.2</length>
          </cylinder>
        </geometry>
      </collision>
      <visual name="wheel_rr_visual">
        <geometry>
          <cylinder>
            <radius>0.3</radius>
            <length>0.2</length>
          </cylinder>
        </geometry>
      </visual>
    </link>

    <joint name="wheel_fl_joint" type="revolute">
      <parent>chassis</parent>
      <child>wheel_fl</child>
      <axis>
        <xyz>0 0 1</xyz>
        <limit>
          <lower>-1e16</lower>
          <upper>1e16</upper>
          <effort>200</effort>
          <velocity>20</velocity>
        </limit>
      </axis>
    </joint>

    <joint name="wheel_fr_joint" type="revolute">
      <parent>chassis</parent>
      <child>wheel_fr</child>
      <axis>
        <xyz>0 0 1</xyz>
        <limit>
          <lower>-1e16</lower>
          <upper>1e16</upper>
          <effort>200</effort>
          <velocity>20</velocity>
        </limit>
      </axis>
    </joint>

    <joint name="wheel_rl_joint" type="revolute">
      <parent>chassis</parent>
      <child>wheel_rl</child>
      <axis>
        <xyz>0 0 1</xyz>
        <limit>
          <lower>-1e16</lower>
          <upper>1e16</upper>
          <effort>200</effort>
          <velocity>20</velocity>
        </limit>
      </axis>
    </joint>

    <joint name="wheel_rr_joint" type="revolute">
      <parent>chassis</parent>
      <child>wheel_rr</child>
      <axis>
        <xyz>0 0 1</xyz>
        <limit>
          <lower>-1e16</lower>
          <upper>1e16</upper>
          <effort>200</effort>
          <velocity>20</velocity>
        </limit>
      </axis>
    </joint>
  </model>
</sdf>
